在Python中，语句用于捕获和处理异常。`try`块中的代码被执行，如果发生异常，则会跳转到相应的`except`块进行异常处理。`except`块可以捕获特定类型的异常，并提供相应的处理逻辑。
`finally`块在Python中是一个异常处理机制的一部分，它包含的代码无论是否发生异常都会被执行。

以下是`try-except`语句的基本语法：

```python
try:
    # 可能会引发异常的代码
    # ...
except ExceptionType1:
    # 处理 ExceptionType1 类型的异常
    # ...
except ExceptionType2:
    # 处理 ExceptionType2 类型的异常
    # ...
except:
    # 处理其他未指定类型的异常
    # ...

final:
	# 最终都会被执行
```

在上述示例中，`try`块中的代码是可能会引发异常的部分。如果其中的代码引发了与`ExceptionType1`匹配的异常，则跳转到第一个`except`块进行处理。如果引发了与`ExceptionType2`匹配的异常，则跳转到第二个`except`块进行处理。如果没有指定异常类型的`except`块，则可以处理任何未被前面的`except`块捕获的异常。

以下是一个简单的示例，演示了`try-except`语句的使用：

```python
try:
    num1 = int(input("Enter a number: "))
    num2 = int(input("Enter another number: "))
    result = num1 / num2
    print("Result:", result)
except ValueError:
    print("Invalid input. Please enter a valid number.")
except ZeroDivisionError:
    print("Error: Division by zero is not allowed.")
except:
    print("An error occurred.")
```

在这个示例中，我们尝试将两个输入的字符串转换为整数，并进行除法运算。如果输入的内容无法转换为整数（`ValueError`异常），我们打印一条错误消息。如果尝试进行除以零的除法操作（`ZeroDivisionError`异常），我们也打印相应的错误消息。对于其他未指定类型的异常，我们打印一条通用错误消息。通过使用`try-except`语句，我们可以在出现异常时捕获并处理它们，以避免程序终止并提供相应的错误处理逻辑。



